<?xml version="1.0" encoding="utf-8"?>
<!-- This URDF was automatically created by SolidWorks to URDF Exporter! Originally created by Stephen Brawner (brawner@gmail.com) 
     Commit Version: 1.5.1-0-g916b5db  Build Version: 1.5.7152.31018
     For more information, please see http://wiki.ros.org/sw_urdf_exporter -->
<robot
  name="Model_fixed">
  <link
    name="base_link">
    <inertial>
      <origin
        xyz="-0.00606939404829831 0.0201490999951633 0.843082728351529"
        rpy="0 0 0" />
      <mass
        value="6.93145376295062" />
      <inertia
        ixx="0.0232965028672791"
        ixy="-2.61815296759581E-07"
        ixz="-8.22791913432519E-07"
        iyy="0.0242233322197322"
        iyz="-1.53624849404293E-05"
        izz="0.015111182265091" />
    </inertial>
    <visual>
      <origin
        xyz="0 0 0"
        rpy="0 0 0" />
      <geometry>
        <mesh
          filename="package://Model_fixed/meshes/base_link.STL" />
      </geometry>
      <material
        name="">
        <color
          rgba="0.752941176470588 0.752941176470588 0.752941176470588 1" />
      </material>
    </visual>
    <collision>
      <origin
        xyz="0 0 0"
        rpy="0 0 0" />
      <geometry>
        <mesh
          filename="package://Model_fixed/meshes/base_link.STL" />
      </geometry>
    </collision>
  </link>
  <link
    name="RFW">
    <inertial>
      <origin
        xyz="0.017684 0 0"
        rpy="0 0 0" />
      <mass
        value="0.19359" />
      <inertia
        ixx="0.00025308"
        ixy="-1.8245E-21"
        ixz="1.6728E-21"
        iyy="0.00013682"
        iyz="-6.7763E-21"
        izz="0.00013682" />
    </inertial>
    <visual>
      <origin
        xyz="0 0 0"
        rpy="0 0 0" />
      <geometry>
        <mesh
          filename="package://Model_fixed/meshes/RFW.STL" />
      </geometry>
      <material
        name="">
        <color
          rgba="1 1 1 1" />
      </material>
    </visual>
    <collision>
      <origin
        xyz="0 0 0"
        rpy="0 0 0" />
      <geometry>
        <mesh
          filename="package://Model_fixed/meshes/RFW.STL" />
      </geometry>
    </collision>
  </link>
  <joint
    name="RFW"
    type="continuous">
    <origin
      xyz="-0.178347230537678 -0.925216287919125 -0.0733733849987262"
      rpy="1.22603373955169 0 3.14159265358979" />
    <parent
      link="base_link" />
    <child
      link="RFW" />
    <axis
      xyz="1 0 0" />
    <limit
      effort="3.1"
      velocity="7" />
  </joint>
  <link
    name="LFW">
    <inertial>
      <origin
        xyz="0.0176842754259269 0 0"
        rpy="0 0 0" />
      <mass
        value="0.193585420779862" />
      <inertia
        ixx="0.000253081141332253"
        ixy="-5.88092833198902E-37"
        ixz="5.17100588748822E-21"
        iyy="0.000136818598566517"
        iyz="7.17557753438366E-37"
        izz="0.000136818598566517" />
    </inertial>
    <visual>
      <origin
        xyz="0 0 0"
        rpy="0 0 0" />
      <geometry>
        <mesh
          filename="package://Model_fixed/meshes/LFW.STL" />
      </geometry>
      <material
        name="">
        <color
          rgba="1 1 1 1" />
      </material>
    </visual>
    <collision>
      <origin
        xyz="0 0 0"
        rpy="0 0 0" />
      <geometry>
        <mesh
          filename="package://Model_fixed/meshes/LFW.STL" />
      </geometry>
    </collision>
  </link>
  <joint
    name="LFW"
    type="continuous">
    <origin
      xyz="0.165152769462322 -0.925216287919125 -0.073370943714424"
      rpy="1.5707963267949 0 0" />
    <parent
      link="base_link" />
    <child
      link="LFW" />
    <axis
      xyz="1 0 0" />
    <limit
      effort="3.1"
      velocity="7" />
  </joint>
  <link
    name="RBW">
    <inertial>
      <origin
        xyz="0.017684 0 0"
        rpy="0 0 0" />
      <mass
        value="0.19359" />
      <inertia
        ixx="0.00025308"
        ixy="1.4759E-22"
        ixz="2.2103E-20"
        iyy="0.00013682"
        iyz="-2.1176E-22"
        izz="0.00013682" />
    </inertial>
    <visual>
      <origin
        xyz="0 0 0"
        rpy="0 0 0" />
      <geometry>
        <mesh
          filename="package://Model_fixed/meshes/RBW.STL" />
      </geometry>
      <material
        name="">
        <color
          rgba="1 1 1 1" />
      </material>
    </visual>
    <collision>
      <origin
        xyz="0 0 0"
        rpy="0 0 0" />
      <geometry>
        <mesh
          filename="package://Model_fixed/meshes/RBW.STL" />
      </geometry>
    </collision>
  </link>
  <joint
    name="RBW"
    type="continuous">
    <origin
      xyz="-0.17835 -0.75522 -0.073373"
      rpy="-3.1322 0 3.1416" />
    <parent
      link="base_link" />
    <child
      link="RBW" />
    <axis
      xyz="1 0 0" />
    <limit
      effort="3.1"
      velocity="7" />
  </joint>
  <link
    name="LBW">
    <inertial>
      <origin
        xyz="0.0176842754259269 0 0"
        rpy="0 0 0" />
      <mass
        value="0.193585420779862" />
      <inertia
        ixx="0.000253081141332253"
        ixy="-5.88092833198902E-37"
        ixz="5.17100588748822E-21"
        iyy="0.000136818598566517"
        iyz="7.17557753438366E-37"
        izz="0.000136818598566517" />
    </inertial>
    <visual>
      <origin
        xyz="0 0 0"
        rpy="0 0 0" />
      <geometry>
        <mesh
          filename="package://Model_fixed/meshes/LBW.STL" />
      </geometry>
      <material
        name="">
        <color
          rgba="1 1 1 1" />
      </material>
    </visual>
    <collision>
      <origin
        xyz="0 0 0"
        rpy="0 0 0" />
      <geometry>
        <mesh
          filename="package://Model_fixed/meshes/LBW.STL" />
      </geometry>
    </collision>
  </link>
  <joint
    name="LBW"
    type="continuous">
    <origin
      xyz="0.16515 -0.75582 -0.073371"
      rpy="1.5708 0 0" />
    <parent
      link="base_link" />
    <child
      link="LBW" />
    <axis
      xyz="1 0 0" />
    <limit
      effort="3.1"
      velocity="7" />
  </joint>
  <link
    name="RFS">
    <inertial>
      <origin
        xyz="2.7756E-17 1.1102E-16 0.0425"
        rpy="0 0 0" />
      <mass
        value="0.2618" />
      <inertia
        ixx="0.00016635"
        ixy="2.1965E-21"
        ixz="-2.1222E-20"
        iyy="0.00016635"
        iyz="-4.4187E-23"
        izz="1.7453E-05" />
    </inertial>
    <visual>
      <origin
        xyz="0 0 0"
        rpy="0 0 0" />
      <geometry>
        <mesh
          filename="package://Model_fixed/meshes/RFS.STL" />
      </geometry>
      <material
        name="">
        <color
          rgba="0.77647 0.75686 0.73725 1" />
      </material>
    </visual>
    <collision>
      <origin
        xyz="0 0 0"
        rpy="0 0 0" />
      <geometry>
        <mesh
          filename="package://Model_fixed/meshes/RFS.STL" />
      </geometry>
    </collision>
  </link>
  <joint
    name="RFS"
    type="fixed">
    <origin
      xyz="-0.1496 -0.93882 -0.024587"
      rpy="0 0 0" />
    <parent
      link="base_link" />
    <child
      link="RFS" />
    <axis
      xyz="0 0 0" />
    <limit
      lower="0"
      upper="0"
      effort="0"
      velocity="0" />
  </joint>
  <link
    name="LFS">
    <inertial>
      <origin
        xyz="0 -1.11022302462516E-16 0.0425"
        rpy="0 0 0" />
      <mass
        value="0.2618" />
      <inertia
        ixx="0.000166352083333334"
        ixy="5.42116197310532E-21"
        ixz="-6.90194305155393E-21"
        iyy="0.000166352083333333"
        iyz="2.17405123128603E-21"
        izz="1.74533333333334E-05" />
    </inertial>
    <visual>
      <origin
        xyz="0 0 0"
        rpy="0 0 0" />
      <geometry>
        <mesh
          filename="package://Model_fixed/meshes/LFS.STL" />
      </geometry>
      <material
        name="">
        <color
          rgba="0.776470588235294 0.756862745098039 0.737254901960784 1" />
      </material>
    </visual>
    <collision>
      <origin
        xyz="0 0 0"
        rpy="0 0 0" />
      <geometry>
        <mesh
          filename="package://Model_fixed/meshes/LFS.STL" />
      </geometry>
    </collision>
  </link>
  <joint
    name="LFS"
    type="fixed">
    <origin
      xyz="0.1364 -0.93882 -0.024586"
      rpy="0 0 0" />
    <parent
      link="base_link" />
    <child
      link="LFS" />
    <axis
      xyz="0 0 0" />
    <limit
      lower="0"
      upper="0"
      effort="0"
      velocity="0" />
  </joint>
  <link
    name="RBS">
    <inertial>
      <origin
        xyz="2.7756E-17 1.1102E-16 0.0425"
        rpy="0 0 0" />
      <mass
        value="0.2618" />
      <inertia
        ixx="0.00016635"
        ixy="3.3201E-21"
        ixz="-1.4207E-20"
        iyy="0.00016635"
        iyz="-5.0309E-20"
        izz="1.7453E-05" />
    </inertial>
    <visual>
      <origin
        xyz="0 0 0"
        rpy="0 0 0" />
      <geometry>
        <mesh
          filename="package://Model_fixed/meshes/RBS.STL" />
      </geometry>
      <material
        name="">
        <color
          rgba="0.77647 0.75686 0.73725 1" />
      </material>
    </visual>
    <collision>
      <origin
        xyz="0 0 0"
        rpy="0 0 0" />
      <geometry>
        <mesh
          filename="package://Model_fixed/meshes/RBS.STL" />
      </geometry>
    </collision>
  </link>
  <joint
    name="RBS"
    type="fixed">
    <origin
      xyz="-0.1496 -0.76882 -0.024587"
      rpy="0 0 0" />
    <parent
      link="base_link" />
    <child
      link="RBS" />
    <axis
      xyz="0 0 0" />
    <limit
      lower="0"
      upper="0"
      effort="0"
      velocity="0" />
  </joint>
  <link
    name="LBS">
    <inertial>
      <origin
        xyz="0 0 0"
        rpy="0 0 0" />
      <mass
        value="0" />
      <inertia
        ixx="0"
        ixy="0"
        ixz="0"
        iyy="0"
        iyz="0"
        izz="0" />
    </inertial>
    <visual>
      <origin
        xyz="0 0 0"
        rpy="0 0 0" />
      <geometry>
        <mesh
          filename="package://Model_fixed/meshes/LBS.STL" />
      </geometry>
      <material
        name="">
        <color
          rgba="1 1 1 1" />
      </material>
    </visual>
    <collision>
      <origin
        xyz="0 0 0"
        rpy="0 0 0" />
      <geometry>
        <mesh
          filename="package://Model_fixed/meshes/LBS.STL" />
      </geometry>
    </collision>
  </link>
  <joint
    name="LBS"
    type="fixed">
    <origin
      xyz="0.136402769462322 -0.768816287919125 -0.0245859437144242"
      rpy="0 0 0" />
    <parent
      link="base_link" />
    <child
      link="LBS" />
    <axis
      xyz="0 0 0" />
    <limit
      lower="0"
      upper="0"
      effort="0"
      velocity="0" />
  </joint>
</robot>